<?xml version='1.0'?>
<sdf version="1.4">
    <model name="scout_robot">
        
        <static>false</static>
        <link name="base">
            <pose>0 0 0.104902 1.570796327 0 1.570796327</pose>
            <inertial>
                <mass>5.119</mass>
                <!--
                <inertia>
                    <ixx>0.0849</ixx>
                    <ixy>0.0</ixy> 
                    <ixz>0.0</ixz> 
                    <iyy>0.1078</iyy>     
                    <iyz>0.0</iyz>      
                    <izz>0.0475</izz>      
                </inertia>
                -->
                <inertia>
                    <ixx>0.0849</ixx>
                    <ixy>0.0</ixy> 
                    <ixz>0.0</ixz> 
                    <iyy>0.1078</iyy>     
                    <iyz>0.0</iyz>      
                    <izz>0.0475</izz>      
                </inertia>
            </inertial>
 
            <collision name="collision">
                <geometry>
                    <mesh>
                        <uri>model://scout/meshes/scout_base_collision.stl</uri>
                        <scale>0.001 0.001 0.001</scale>
                    </mesh>
                    
                </geometry>
                <surface>
            <friction>
              <ode>
                <mu>.7</mu>
                <mu2>.7</mu2>
                <slip1>0.5</slip1>
                <slip2>0.5</slip2>
              </ode>
            </friction>
          </surface>
            </collision>
            <visual name="visual">

                <geometry>
                    <mesh>
                        <uri>model://scout/meshes/scout_base.stl</uri>
                        <scale>0.001 0.001 0.001</scale>
                    </mesh>
                </geometry>
            </visual>
        </link>
        <link name="midleft_wheel">
            <pose>0.0 0.176911 0.031115 0 1.5707 1.5707</pose>
             <inertial>
                <mass>0.0591</mass>
                <inertia>
                    <ixx>0.0000170233</ixx>
                    <ixy>0.0</ixy> 
                    <ixz>0.0</ixz> 
                    <iyy>0.0000170233</iyy>     
                    <iyz>0.0</iyz>      
                    <izz>0.0000286554</izz>      
                </inertia>
            </inertial>
            <collision name="collision">
                <geometry>
                    <cylinder>
                        <radius>0.031115</radius>
                        <length>0.023368</length>
                    </cylinder>
                </geometry>
                <surface>
                    <friction>
                      <ode>
                        <mu>10</mu>
                        <mu2>10</mu2>
                        <slip1>100</slip1>
                        <slip2>100</slip2>
                        <fdir1>0 1 0</fdir1>
                      </ode>
                    </friction>
                </surface>
            </collision>
            <visual name="visual">
                <geometry>
                    <cylinder>
                        <radius>0.031115</radius>
                        <length>0.023368</length>
                    </cylinder>
                </geometry>
            </visual>
        </link>
        <link name="midright_wheel">
            <pose>0.0 -0.176911 0.031115 0 1.5707 1.5707</pose>
            <inertial>
                <mass>0.0591</mass>
                <inertia>
                    <ixx>0.0000170233</ixx>
                    <ixy>0.0</ixy> 
                    <ixz>0.0</ixz> 
                    <iyy>0.0000170233</iyy>     
                    <iyz>0.0</iyz>      
                    <izz>0.0000286554</izz>      
                </inertia>
            </inertial>
            <collision name="collision">
                <geometry>
                    <cylinder>
                        <radius>0.031115</radius>
                        <length>0.023368</length>
                    </cylinder>
                </geometry>
                <surface>
                    <friction>
                      <ode>
                        <mu>10</mu>
                        <mu2>10</mu2>
                        <slip1>100</slip1>
                        <slip2>100</slip2>
                        <fdir1>0 1 0</fdir1>
                      </ode>
                    </friction>
                </surface>
            </collision>
            <visual name="visual">
                <geometry>
                    <cylinder>
                        <radius>0.031115</radius>
                        <length>0.023368</length>
                    </cylinder>
                </geometry>
            </visual>
        </link>
        <link name="frontleft_wheel">
            <pose>0.1143 0.176911 0.079502 0 1.5707 1.5707</pose>
            
            <inertial>
                <mass>1.724</mass>
                <inertia>
                    <ixx>0.00266</ixx>
                    <ixy>0.0</ixy> 
                    <ixz>0.0</ixz> 
                    <iyy>0.00266</iyy>     
                    <iyz>0.0</iyz>      
                    <izz>0.00507476</izz>      
                </inertia>
            </inertial>
            <collision name="collision">
                <geometry>
                    <cylinder>
                        <radius>0.0766826</radius>
                        <length>0.029718</length>
                    </cylinder>
                </geometry>
                <surface>
                    <friction>
                      <ode>
                        <mu>.7</mu>
                        <mu2>.7</mu2>
                        <slip1>0.5</slip1>
                        <slip2>0.5</slip2>
                        <fdir1>0 1 0</fdir1>
                      </ode>
                    </friction>
                </surface>
            </collision>
            <visual name="visual">
                <geometry>
                    <cylinder>
                        <radius>0.0766826</radius>
                        <length>0.029718</length>
                    </cylinder>
                </geometry>
            </visual>
        </link>
        <link name="backleft_wheel">
            <pose>-0.1143 0.176911 0.079502 0 1.5707 1.5707</pose>
            <inertial>
                <mass>1.724</mass>
                <inertia>
                    <ixx>0.00266</ixx>
                    <ixy>0.0</ixy> 
                    <ixz>0.0</ixz> 
                    <iyy>0.00266</iyy>     
                    <iyz>0.0</iyz>      
                    <izz>0.00507476</izz>      
                </inertia>
            </inertial>
            <collision name="collision">
                <geometry>
                    <cylinder>
                        <radius>0.0766826</radius>
                        <length>0.029718</length>
                    </cylinder>
                </geometry>
                <surface>
                    <friction>
                      <ode>
                        <mu>.7</mu>
                        <mu2>.7</mu2>
                        <slip1>0.5</slip1>
                        <slip2>0.5</slip2>
                        <fdir1>0 1 0</fdir1>
                      </ode>
                    </friction>
                </surface>
            </collision>
            <visual name="visual">
                <geometry>
                    <cylinder>
                        <radius>0.0766826</radius>
                        <length>0.029718</length>
                    </cylinder>
                </geometry>
            </visual>
        </link>
        <link name="frontright_wheel">
            <pose>0.1143 -0.176911 0.079502 0 1.5707 1.5707</pose>
            <inertial>
                <mass>1.724</mass>
                <inertia>
                    <ixx>0.00266</ixx>
                    <ixy>0.0</ixy> 
                    <ixz>0.0</ixz> 
                    <iyy>0.00266</iyy>     
                    <iyz>0.0</iyz>      
                    <izz>0.00507476</izz>      
                </inertia>
            </inertial>
            <collision name="collision">
                <geometry>
                    <cylinder>
                        <radius>0.0766826</radius>
                        <length>0.029718</length>
                    </cylinder>
                </geometry>
                <surface>
                    <friction>
                      <ode>
                        <mu>.7</mu>
                        <mu2>.7</mu2>
                        <slip1>0.5</slip1>
                        <slip2>0.5</slip2>
                        <fdir1>0 1 0</fdir1>
                      </ode>
                    </friction>
                </surface>
            </collision>
            <visual name="visual">
                <geometry>
                    <cylinder>
                        <radius>0.0766826</radius>
                        <length>0.029718</length>
                    </cylinder>
                </geometry>
            </visual>
        </link>
        <link name="backright_wheel">
            <pose>-0.1143 -0.176911 0.079502 0 1.5707 1.5707</pose>
            <inertial>
                <mass>1.724</mass>
                <inertia>
                    <ixx>0.00266</ixx>
                    <ixy>0.0</ixy> 
                    <ixz>0.0</ixz> 
                    <iyy>0.00266</iyy>     
                    <iyz>0.0</iyz>      
                    <izz>0.00507476</izz>      
                </inertia>
            </inertial>
            <collision name="collision">
                <geometry>
                    <cylinder>
                        <radius>0.0766826</radius>
                        <length>0.029718</length>
                    </cylinder>
                </geometry>
                <surface>
                    <friction>
                      <ode>
                        <mu>.7</mu>
                        <mu2>.7</mu2>
                        <slip1>0.5</slip1>
                        <slip2>0.5</slip2>
                        <fdir1>0 1 0</fdir1>
                      </ode>
                    </friction>
                </surface>
            </collision>
            <visual name="visual">
                <geometry>
                    <cylinder>
                        <radius>0.0766826</radius>
                        <length>0.029718</length>
                    </cylinder>
                </geometry>
            </visual>
        </link>
        <joint type="revolute" name="frontleft_wheel_joint">
            <pose>0 0 0.0 0 0 0</pose>
            <child>frontleft_wheel</child>
            <parent>base</parent>
            <axis>
                <xyz>0 1 0</xyz>
                <dynamics>
                    <friction>.1</friction>
                </dynamics>
            </axis>
        </joint>
        <joint type="revolute" name="frontright_wheel_joint">
            <pose>0 0 0.0 0 0 0</pose>
            <child>frontright_wheel</child>
            <parent>base</parent>
            <axis>
                <xyz>0 1 0</xyz>
                <dynamics>
                    <friction>.1</friction>
                </dynamics>
            </axis>
        </joint>
        <joint type="revolute" name="backleft_wheel_joint">
            <pose>0 0 0.0 0 0 0</pose>
            <child>backleft_wheel</child>
            <parent>base</parent>
            <axis>
                <xyz>0 1 0</xyz>
                <dynamics>
                    <friction>.1</friction>
                </dynamics>
            </axis>
        </joint>
        <joint type="revolute" name="backright_wheel_joint">
            <pose>0 0 0.0 0 0 0</pose>
            <child>backright_wheel</child>
            <parent>base</parent>
            <axis>
                <xyz>0 1 0</xyz>
                <dynamics>
                    <friction>.1</friction>
                </dynamics>
            </axis>
        </joint>
        <joint type="revolute" name="midleft_wheel_joint">
            <pose>0 0 0.0 0 0 0</pose>
            <child>midleft_wheel</child>
            <parent>base</parent>
            <axis>
                <xyz>0 1 0</xyz>
                <dynamics>
                    <friction>.1</friction>
                </dynamics>
            </axis>
        </joint>
        <joint type="revolute" name="midright_wheel_joint">
            <pose>0 0 0.0 0 0 0</pose>
            <child>midright_wheel</child>
            <parent>base</parent>
            <axis>
                <xyz>0 1 0</xyz>
                <dynamics>
                    <friction>.1</friction>
                </dynamics>
            </axis>
        </joint>        
    </model>

</sdf>
