<?xml version='1.0'?>
<sdf version="1.4">
    <model name="scout_robot">
        
        <static>false</static>
        <link name="base">
            <pose>0 0 0.104902 1.570796327 0 1.570796327</pose>
            <inertial>
                <mass>5.119</mass>
                <inertia>
                    <ixx>0.0849</ixx>
                    <ixy>0.0</ixy> 
                    <ixz>0.0</ixz> 
                    <iyy>0.1078</iyy>     
                    <iyz>0.0</iyz>      
                    <izz>0.0475</izz>      
                </inertia>
            </inertial>
 
            <collision name="collision">
                <geometry>
                    <mesh>
                        <uri>model://scout/meshes/scout_base_collision.stl</uri>
                        <scale>0.001 0.001 0.001</scale>
                    </mesh>
                    
                </geometry>
                <surface>
            <friction>
              <ode>
                <mu>.7</mu>
                <mu2>.7</mu2>
                <slip1>0.5</slip1>
                <slip2>0.5</slip2>
              </ode>
            </friction>
          </surface>
            </collision>
            <visual name="visual">

                <geometry>
                    <mesh>
                        <uri>model://scout/meshes/scout_base.stl</uri>
                        <scale>0.001 0.001 0.001</scale>
                    </mesh>
                </geometry>
            </visual>
        </link>
        <include>
            <uri>model://mid_wheel</uri>
            <name>midleft_wheel</name>
            <pose>0.0 0.176911 0.031115 0 1.5707 1.5707</pose>
        </include>
        <include>
            <uri>model://mid_wheel</uri>
            <name>midright_wheel</name>
            <pose>0.0 -0.176911 0.031115 0 1.5707 1.5707</pose>
        </include>
        <include>
            <uri>model://large_wheel</uri>
            <name>frontleft_wheel</name>
            <pose>0.1143 0.176911 0.079502 0 1.5707 1.5707</pose>
        </include>
        <include>
            <uri>model://large_wheel</uri>
            <name>frontright_wheel</name>
            <pose>0.1143 -0.176911 0.079502 0 1.5707 1.5707</pose>
        </include>
        <include>
            <uri>model://large_wheel</uri>
            <name>backleft_wheel</name>
            <pose>-0.1143 0.176911 0.079502 0 1.5707 1.5707</pose>
        </include>
        <include>
            <uri>model://large_wheel</uri>
            <name>backright_wheel</name>
            <pose>-0.1143 -0.176911 0.079502 0 1.5707 1.5707</pose>
        </include>
        <!--
        <link name="boom">
            <pose>0.233934 0 0.1172972 1.570796327 0 1.570796327</pose>
            <inertial>
                <mass>0.063049339</mass>
                <inertia>
                    <ixx>0.000184004</ixx>
                    <ixy>0.0</ixy> 
                    <ixz>0.0</ixz> 
                    <iyy>0.000221215</iyy>     
                    <iyz>0.0</iyz>      
                    <izz>0.0000506</izz>      
                </inertia>
            </inertial>
            <collision name="collision">
                <geometry>
                    <box>
                        <size>.127 .1 .254</size>
                    </box>
                </geometry>
                <surface>
                    <friction>
                      <ode>
                        <mu>.7</mu>
                        <mu2>.7</mu2>
                        <slip1>0.5</slip1>
                        <slip2>0.5</slip2>
                        <fdir1>0 1 0</fdir1>
                      </ode>
                    </friction>
                </surface>
            </collision>
            <visual name="visual">
            <geometry>
                <mesh>
                    <uri>model://scout/meshes/365001.stl</uri>
                    <scale>0.001 0.001 0.001</scale>
                </mesh>
            </geometry>
            </visual>
        </link>
        -->
        <joint type="revolute" name="frontleft_wheel_joint">
            <pose frame=''>0 0 0 0 0 0</pose>
            <child>frontleft_wheel::large_wheel</child>
            <parent>base</parent>
            <axis>
                <xyz>0 1 0</xyz>
                <dynamics>
                    <damping>0</damping>
                </dynamics>
            </axis>
            <physics>
                <ode>
                    <limit>
                        <cfm>0</cfm>
                        <erp>0.2</erp>
                    </limit>
                    <suspension>
                        <cfm>0</cfm>
                        <erp>0.2</erp>
                    </suspension>
                </ode>
            </physics>
        </joint>
        <joint type="revolute" name="frontright_wheel_joint">
            <pose frame=''>0 0 0 0 0 0</pose>
            <child>frontright_wheel::large_wheel</child>
            <parent>base</parent>
            <axis>
                <xyz>0 1 0</xyz>
                <dynamics>
                    <damping>0</damping>
                </dynamics>
            </axis>
            <physics>
                <ode>
                    <limit>
                        <cfm>0</cfm>
                        <erp>0.2</erp>
                    </limit>
                    <suspension>
                        <cfm>0</cfm>
                        <erp>0.2</erp>
                    </suspension>
                </ode>
            </physics>
        </joint>
        <joint type="revolute" name="backleft_wheel_joint">
            <pose frame=''>0 0 0 0 0 0</pose>
            <child>backleft_wheel::large_wheel</child>
            <parent>base</parent>
            <axis>
                <xyz>0 1 0</xyz>
                <dynamics>
                    <damping>0</damping>
                </dynamics>
            </axis>
            <physics>
                <ode>
                    <limit>
                        <cfm>0</cfm>
                        <erp>0.2</erp>
                    </limit>
                    <suspension>
                        <cfm>0</cfm>
                        <erp>0.2</erp>
                    </suspension>
                </ode>
            </physics>
        </joint>
        <joint type="revolute" name="backright_wheel_joint">
            <pose frame=''>0 0 0 0 0 0</pose>
            <child>backright_wheel::large_wheel</child>
            <parent>base</parent>
            <axis>
                <xyz>0 1 0</xyz>
                <dynamics>
                    <damping>0</damping>
                </dynamics>
            </axis>
            <physics>
                <ode>
                    <limit>
                        <cfm>0</cfm>
                        <erp>0.2</erp>
                    </limit>
                    <suspension>
                        <cfm>0</cfm>
                        <erp>0.2</erp>
                    </suspension>
                </ode>
            </physics>
        </joint>
        
        <joint type="revolute" name="midleft_wheel_joint">
            <child>midleft_wheel::mid_wheel</child>
            <parent>base</parent>
            <axis>
                <xyz>0 1 0</xyz>
                <dynamics>
                    <damping>0</damping>
                </dynamics>
            </axis>
            <physics>
                <ode>
                    <limit>
                        <cfm>0</cfm>
                        <erp>0.2</erp>
                    </limit>
                    <suspension>
                        <cfm>0</cfm>
                        <erp>0.2</erp>
                    </suspension>
                </ode>
            </physics>
        </joint> 
        
        <joint type="revolute" name="midright_wheel_joint">
            <child>midright_wheel::mid_wheel</child>
            <parent>base</parent>
            <axis>
                <xyz>0 1 0</xyz>
                <dynamics>
                    <damping>0</damping>
                </dynamics>
            </axis>
            <physics>
                <ode>
                    <limit>
                        <cfm>0</cfm>
                        <erp>0.2</erp>
                    </limit>
                    <suspension>
                        <cfm>0</cfm>
                        <erp>0.2</erp>
                    </suspension>
                </ode>
            </physics>
        </joint> 
        <!--
        <joint type="revolute" name="boom_base_joint">
            <child>boom</child>
            <parent>base</parent>
            <axis>
                <xyz>0 1 0</xyz>
                <dynamics>
                    <damping>0</damping>
                </dynamics>
            </axis>
            <physics>
                <ode>
                    <limit>
                        <cfm>0</cfm>
                        <erp>0.2</erp>
                    </limit>
                    <suspension>
                        <cfm>0</cfm>
                        <erp>0.2</erp>
                    </suspension>
                </ode>
            </physics>
        </joint>  
        -->     
    </model>

</sdf>
